<?xml version="1.0" ?>
<!-- =================================================================================== -->
<!-- |    This document was autogenerated by xacro from jubot_box.xacro                | -->
<!-- |    EDITING THIS FILE BY HAND IS NOT RECOMMENDED                                 | -->
<!-- =================================================================================== -->
<robot name="jubox">
  <link name="base_link">
    <visual>
      <origin rpy="0.0 0.0 0.0" xyz="0.0 0.0 0.12"/>
      <geometry>
        <box size="0.67 0.53 0.10"/>
      </geometry>
      <material name="white">
        <color rgba="1 1 1 1"/>
      </material>
    </visual>
    <collision>
      <geometry>
        <box size="0.67 0.53 0.10"/>
      </geometry>
      <origin rpy="0.0 0.0 0.0" xyz="0.0 0.0 0.0"/>
    </collision>
    <inertial>
      <mass value="2"/>
      <inertia ixx="0.07648333333333335" ixy="0" ixz="0" iyy="0.12163333333333336" iyz="0" izz="0.048483333333333344"/>
    </inertial>
  </link>
  <gazebo reference="base_link">
    <material>Gazebo/White</material>
  </gazebo>
  <joint name="left_back_joint" type="continuous">
    <origin rpy="1.57079635 0.0 0.0" xyz="-0.2 0.298 0.07"/>
    <parent link="base_link"/>
    <child link="left_back_link"/>
    <axis xyz="0 0 1"/>
  </joint>
  <link name="left_back_link">
    <visual>
      <origin rpy="0.0 0.0 0.0" xyz="0.0 0.0 0.0"/>
      <geometry>
        <cylinder length="0.04" radius="0.13"/>
      </geometry>
      <material name="black">
        <color rgba="0 0 0 1"/>
      </material>
    </visual>
    <collision>
      <geometry>
        <cylinder length="0.04" radius="0.13"/>
      </geometry>
      <origin rpy="0.0 0.0 0.0" xyz="0.0 0.0 0.0"/>
    </collision>
    <inertial>
      <mass value="0.05"/>
      <inertia ixx="0.0002179166666666667" ixy="0" ixz="0" iyy="0.0002179166666666667" iyz="0" izz="0.0004225000000000001"/>
    </inertial>
  </link>
  <gazebo reference="left_back_link">
    <material>Gazebo/Black</material>
  </gazebo>
  <joint name="right_back_joint" type="continuous">
    <origin rpy="1.57079635 0.0 0.0" xyz="-0.2 -0.298 0.07"/>
    <parent link="base_link"/>
    <child link="right_back_link"/>
    <axis xyz="0 0 1"/>
  </joint>
  <link name="right_back_link">
    <visual>
      <origin rpy="0.0 0.0 0.0" xyz="0.0 0.0 0.0"/>
      <geometry>
        <cylinder length="0.04" radius="0.13"/>
      </geometry>
      <material name="black">
        <color rgba="0 0 0 1"/>
      </material>
    </visual>
    <collision>
      <geometry>
        <cylinder length="0.04" radius="0.13"/>
      </geometry>
      <origin rpy="0.0 0.0 0.0" xyz="0.0 0.0 0.0"/>
    </collision>
    <inertial>
      <mass value="0.05"/>
      <inertia ixx="0.0002179166666666667" ixy="0" ixz="0" iyy="0.0002179166666666667" iyz="0" izz="0.0004225000000000001"/>
    </inertial>
  </link>
  <gazebo reference="right_back_link">
    <material>Gazebo/Black</material>
  </gazebo>
  <joint name="left_front_joint" type="continuous">
    <origin rpy="1.57079635 0.0 0.0" xyz="0.2 0.298 0.07"/>
    <parent link="base_link"/>
    <child link="left_front_link"/>
    <axis xyz="0 0 1"/>
  </joint>
  <link name="left_front_link">
    <visual>
      <origin rpy="0.0 0.0 0.0" xyz="0.0 0.0 0.0"/>
      <geometry>
        <cylinder length="0.04" radius="0.13"/>
      </geometry>
      <material name="black">
        <color rgba="0 0 0 1"/>
      </material>
    </visual>
    <collision>
      <geometry>
        <cylinder length="0.04" radius="0.13"/>
      </geometry>
      <origin rpy="0.0 0.0 0.0" xyz="0.0 0.0 0.0"/>
    </collision>
    <inertial>
      <mass value="0.05"/>
      <inertia ixx="0.0002179166666666667" ixy="0" ixz="0" iyy="0.0002179166666666667" iyz="0" izz="0.0004225000000000001"/>
    </inertial>
  </link>
  <gazebo reference="left_front_link">
    <material>Gazebo/Black</material>
  </gazebo>
  <joint name="right_front_joint" type="continuous">
    <origin rpy="1.57079635 0.0 0.0" xyz="0.2 -0.298 0.07"/>
    <parent link="base_link"/>
    <child link="right_front_link"/>
    <axis xyz="0 0 1"/>
  </joint>
  <link name="right_front_link">
    <visual>
      <origin rpy="0.0 0.0 0.0" xyz="0.0 0.0 0.0"/>
      <geometry>
        <cylinder length="0.04" radius="0.13"/>
      </geometry>
      <material name="black">
        <color rgba="0 0 0 1"/>
      </material>
    </visual>
    <collision>
      <geometry>
        <cylinder length="0.04" radius="0.13"/>
      </geometry>
      <origin rpy="0.0 0.0 0.0" xyz="0.0 0.0 0.0"/>
    </collision>
    <inertial>
      <mass value="0.05"/>
      <inertia ixx="0.0002179166666666667" ixy="0" ixz="0" iyy="0.0002179166666666667" iyz="0" izz="0.0004225000000000001"/>
    </inertial>
  </link>
  <gazebo reference="right_front_link">
    <material>Gazebo/Black</material>
  </gazebo>
  <!--support-->
  <joint name="zhu1_joint" type="fixed">
    <origin rpy="1.57079635 0.0 0.0" xyz="0.3 -0.24 0.22"/>
    <parent link="base_link"/>
    <child link="zhu1_link"/>
  </joint>
  <link name="zhu1_link">
    <visual>
      <origin rpy="0.0 0.0 0.0" xyz="0.0 0.0 0.0"/>
      <geometry>
        <box size="0.04 0.11 0.04"/>
      </geometry>
      <material name="white">
        <color rgba="1 1 1 0"/>
      </material>
    </visual>
    <collision>
      <geometry>
        <box size="0.04 0.11 0.04"/>
      </geometry>
      <origin rpy="0.0 0.0 0.0" xyz="0.0 0.0 0.0"/>
    </collision>
    <inertial>
      <mass value="0.02"/>
      <inertia ixx="2.2833333333333334e-05" ixy="0" ixz="0" iyy="5.3333333333333345e-06" iyz="0" izz="2.2833333333333334e-05"/>
    </inertial>
  </link>
  <gazebo reference="zhu1_link">
    <material>Gazebo/White</material>
  </gazebo>
  <joint name="zhu2_joint" type="fixed">
    <origin rpy="1.57079635 0.0 0.0" xyz="0.3 0.24 0.22"/>
    <parent link="base_link"/>
    <child link="zhu2_link"/>
  </joint>
  <link name="zhu2_link">
    <visual>
      <origin rpy="0.0 0.0 0.0" xyz="0.0 0.0 0.0"/>
      <geometry>
        <box size="0.04 0.11 0.04"/>
      </geometry>
      <material name="white">
        <color rgba="1 1 1 0"/>
      </material>
    </visual>
    <collision>
      <geometry>
        <box size="0.04 0.11 0.04"/>
      </geometry>
      <origin rpy="0.0 0.0 0.0" xyz="0.0 0.0 0.0"/>
    </collision>
    <inertial>
      <mass value="0.02"/>
      <inertia ixx="2.2833333333333334e-05" ixy="0" ixz="0" iyy="5.3333333333333345e-06" iyz="0" izz="2.2833333333333334e-05"/>
    </inertial>
  </link>
  <gazebo reference="zhu2_link">
    <material>Gazebo/White</material>
  </gazebo>
  <joint name="zhu3_joint" type="fixed">
    <origin rpy="1.57079635 0.0 0.0" xyz="-0.3 0.24 0.22"/>
    <parent link="base_link"/>
    <child link="zhu3_link"/>
  </joint>
  <link name="zhu3_link">
    <visual>
      <origin rpy="0.0 0.0 0.0" xyz="0.0 0.0 0.0"/>
      <geometry>
        <box size="0.04 0.11 0.04"/>
      </geometry>
      <material name="white">
        <color rgba="1 1 1 0"/>
      </material>
    </visual>
    <collision>
      <geometry>
        <box size="0.04 0.11 0.04"/>
      </geometry>
      <origin rpy="0.0 0.0 0.0" xyz="0.0 0.0 0.0"/>
    </collision>
    <inertial>
      <mass value="0.02"/>
      <inertia ixx="2.2833333333333334e-05" ixy="0" ixz="0" iyy="5.3333333333333345e-06" iyz="0" izz="2.2833333333333334e-05"/>
    </inertial>
  </link>
  <gazebo reference="zhu3_link">
    <material>Gazebo/White</material>
  </gazebo>
  <joint name="zhu4_joint" type="fixed">
    <origin rpy="1.57079635 0.0 0.0" xyz="-0.3 -0.24 0.22"/>
    <parent link="base_link"/>
    <child link="zhu4_link"/>
  </joint>
  <link name="zhu4_link">
    <visual>
      <origin rpy="0.0 0.0 0.0" xyz="0.0 0.0 0.0"/>
      <geometry>
        <box size="0.04 0.11 0.04"/>
      </geometry>
      <material name="white">
        <color rgba="1 1 1 0"/>
      </material>
    </visual>
    <collision>
      <geometry>
        <box size="0.04 0.11 0.04"/>
      </geometry>
      <origin rpy="0.0 0.0 0.0" xyz="0.0 0.0 0.0"/>
    </collision>
    <inertial>
      <mass value="0.02"/>
      <inertia ixx="2.2833333333333334e-05" ixy="0" ixz="0" iyy="5.3333333333333345e-06" iyz="0" izz="2.2833333333333334e-05"/>
    </inertial>
  </link>
  <gazebo reference="zhu4_link">
    <material>Gazebo/White</material>
  </gazebo>
  <!--base2_link-->
  <joint name="er_joint" type="fixed">
    <origin rpy="0 0.0 0.0" xyz="0 0 0.27"/>
    <parent link="base_link"/>
    <child link="er_link"/>
  </joint>
  <link name="er_link">
    <visual>
      <origin rpy="0.0 0.0 0.0" xyz="0.0 0.0 0.0"/>
      <geometry>
        <box size="0.67 0.53 0.08"/>
      </geometry>
      <material name="white">
        <color rgba="1 1 1 0"/>
      </material>
    </visual>
    <collision>
      <geometry>
        <box size="0.67 0.53 0.08"/>
      </geometry>
      <origin rpy="0.0 0.0 0.0" xyz="0.0 0.0 0.0"/>
    </collision>
    <inertial>
      <mass value="1"/>
      <inertia ixx="0.03794166666666667" ixy="0" ixz="0" iyy="0.06081666666666668" iyz="0" izz="0.02394166666666667"/>
    </inertial>
  </link>
  <gazebo reference="er_link">
    <material>Gazebo/White</material>
  </gazebo>
</robot>

