<?xml version="1.0" ?>
<robot name="jubox" xmlns:xacro="http://wiki.ros.org/xacro">    
    
    <xacro:include filename="head.xacro"/>
<!--base_car-->
    <xacro:property name="base_mass" value="2" />
    <xacro:property name="base_length" value="0.67" />
    <xacro:property name="base_weigth" value="0.53" />
    <xacro:property name="base_heigth" value="0.10" />



    <link name="base_link">   
        <visual> 
            <origin xyz="0.0 0.0 0.12" rpy="0.0 0.0 0.0"/> 
            <geometry>  
                <box size="0.67 0.53 0.10"/>            
            </geometry>
            <material name="white"> 
                <color rgba="1 1 1 1"/>  
            </material>
        </visual>
    <collision>
        <geometry>  
            <box size="0.67 0.53 0.10"/>            
        </geometry>
        <origin xyz="0.0 0.0 0.0" rpy="0.0 0.0 0.0"/> 
    </collision>
    <xacro:Box_inertial_matrix m="${base_mass}"  l="${base_length}" w="${base_weigth}" h="${base_heigth}" />    
    </link>
    <gazebo reference="base_link">
        <material>Gazebo/White</material>
    </gazebo>
    
    
<!--wheel-->
    <xacro:property name="wheel_radius" value="0.13" />
    <xacro:property name="wheel_length" value="0.04" />
    <xacro:property name="wheel_mass" value="0.05" />

    <xacro:property name="PI" value="3.1415927" />

    <xacro:macro name="wheel_func" params="wheel_name flag1 flag2">

    <joint name="${wheel_name}_joint" type="continuous">   
        <origin xyz="${0.20*flag2} ${0.298*flag1} 0.07" rpy="${PI/2} 0.0 0.0"/> 
        <parent link="base_link"/>  
        <child link="${wheel_name}_link"/> 
        <axis xyz="0 0 1"/>  
    </joint>

    <link name="${wheel_name}_link">
        <visual>
            <origin xyz="0.0 0.0 0.0" rpy="0.0 0.0 0.0"/>
            <geometry>
                <cylinder radius="${wheel_radius}" length="${wheel_length}"/>
            </geometry>
            <material name="black">
                <color rgba="0 0 0 1"/>
            </material>
        </visual>
    <collision>
        <geometry>  
            <cylinder radius="${wheel_radius}" length="${wheel_length}"/>             
        </geometry>
        <origin xyz="0.0 0.0 0.0" rpy="0.0 0.0 0.0"/> 
    </collision>
    <xacro:cylinder_inertial_matrix m="${wheel_mass}" r="${wheel_radius}" h="${wheel_length}" />    
    </link>
    <gazebo reference="${wheel_name}_link">
        <material>Gazebo/Black</material>
    </gazebo>

</xacro:macro>   

    <xacro:wheel_func wheel_name="left_back" flag1="1" flag2="-1"/>
    <xacro:wheel_func wheel_name="right_back" flag1="-1" flag2="-1"/>
    <xacro:wheel_func wheel_name="left_front" flag1="1" flag2="1"/>
    <xacro:wheel_func wheel_name="right_front" flag1="-1" flag2="1"/>
    
    
    
<!--support-->

    <xacro:property name="support_l" value="0.04" />
    <xacro:property name="support_h" value="0.11" />
    <xacro:property name="support_w" value="0.04" />
    <xacro:property name="support_mass" value="0.02" />
    <xacro:property name="PI" value="3.1415927" />

<xacro:macro name="support_func" params="support_name flag1 flag2">

    <joint name="${support_name}_joint" type="fixed">
        <origin xyz="${0.3*flag1} ${0.24*flag2} 0.22" rpy="${PI/2} 0.0 0.0"/>
        <parent link="base_link"/>
        <child link="${support_name}_link"/>   
    </joint>

    <link name="${support_name}_link">
        <visual>
            <origin xyz="0.0 0.0 0.0" rpy="0.0 0.0 0.0"/>
            <geometry>
                <box size="${support_l} ${support_h} ${support_w}"/>
            </geometry>
            <material name="white">
                <color rgba="1 1 1 0"/>
            </material>
        </visual>
    <collision>
        <geometry>  
            <box size="${support_l} ${support_h} ${support_w}"/>         
        </geometry>
        <origin xyz="0.0 0.0 0.0" rpy="0.0 0.0 0.0"/> 
    </collision>
    <xacro:Box_inertial_matrix m="${support_mass}"  l="${support_l}" w="${support_w}" h="${support_h}" />    
    </link>
    <gazebo reference="${support_name}_link">
        <material>Gazebo/White</material>
    </gazebo>

</xacro:macro>   

    <xacro:support_func support_name="zhu1" flag1="1" flag2="-1"/>
    <xacro:support_func support_name="zhu2" flag1="1" flag2="1"/>
    <xacro:support_func support_name="zhu3" flag1="-1" flag2="1"/>
    <xacro:support_func support_name="zhu4" flag1="-1" flag2="-1"/>


<!--base2_link-->

    <xacro:property name="base2_mass" value="1" />
    <xacro:property name="base2_l" value="0.67" />
    <xacro:property name="base2_w" value="0.53" />
    <xacro:property name="base2_h" value="0.08" />


    <joint name="er_joint" type="fixed">
        <origin xyz="0 0 0.27" rpy="0 0.0 0.0"/>
        <parent link="base_link"/>
        <child link="er_link"/>   
    </joint>

    <link name="er_link">
        <visual>
            <origin xyz="0.0 0.0 0.0" rpy="0.0 0.0 0.0"/>
            <geometry>
                 <box size="${base2_l} ${base2_w} ${base2_h}"/>
            </geometry>
            <material name="white">
                <color rgba="1 1 1 0"/>
            </material>
        </visual>
    <collision>
        <geometry>  
            <box size="0.67 0.53 0.08"/>      
        </geometry>
        <origin xyz="0.0 0.0 0.0" rpy="0.0 0.0 0.0"/> 
    </collision>
    <xacro:Box_inertial_matrix m="${base2_mass}"  l="${base2_l}" w="${base2_w}" h="${base2_h}" />    
    </link>
    <gazebo reference="er_link">
        <material>Gazebo/White</material>
    </gazebo> 
</robot>
