<?xml version="1.0" ?>
<robot name="my_simulation">
  <link name="chassis">
    <inertial>
      <mass value="1" />
      <inertia ixx="0.1" ixy="0" ixz="0" iyy="0.1" iyz="0" izz="0.1" />
    </inertial>
    <collision name="chassis_collision">
      <geometry>
        <box size="0.5 0.5 0.2" />
      </geometry>
      <max_contacts>10</max_contacts>
      <surface>
        <contact>
          <ode />
        </contact>
        <friction>
          <ode />
        </friction>
      </surface>
    </collision>
    <visual name="chassis_visual">
      <geometry>
        <box size="0.5 0.5 0.2" />
      </geometry>
      <material>
        <script>
          <name>Gazebo/Blue</name>
          <uri>file://media/materials/scripts/gazebo.material</uri>
        </script>
      </material>
    </visual>
  </link>
  <joint name="wheel_joint" type="revolute">
    <parent>chassis</parent>
    <child>wheel</child>
    <axis>0 0 1</axis>
    <limit>
      <effort>10</effort>
      <velocity>10</velocity>
    </limit>
  </joint>
  <link name="wheel">
    <inertial>
      <mass value="0.1" />
      <inertia ixx="0.01" ixy="0" ixz="0" iyy="0.01" iyz="0" izz="0.01" />
    </inertial>
    <collision name="wheel_collision">
      <geometry>
        <box size="0.5 0.5 0.2" />
      </geometry>
      <max_contacts>10</max_contacts>
      <surface>
        <contact>
          <ode />
        </contact>
        <friction>
          <ode />
        </friction>
      </surface>
    </collision>
    <visual name="wheel_visual">
      <geometry>
        <box size="0.5 0.5 0.2" />
      </geometry>
      <material>
        <script>
          <name>Gazebo/Blue</name>
          <uri>file://media/materials/

